Workbook

Sheet 1 · Summary
A1: Quantum Force 9000 — DPU Acceleration Card
A2: What it takes to deliver the solution · dynamic investment, risk & delivery model (expanded from Slide 15)
A4: Metric | B4: Value | C4: Basis / source | D4: Assumption
A5: Objective | B5: TP+TLS: 10.1G → 25G+ | C5: CP Appliance Comparison Chart 2026 | D5: Lift Threat-Prevention throughput with TLS inspection on; PoC success gate
A6: Approach | B6: Reuse NVIDIA BlueField-3 (DOCA) | C6: Check Point AI Cloud Protect (AIFF) press release | D6: Not an own ASIC and not a self-designed FPGA — fastest, lowest-risk path
A7: Expected throughput multiple | B7: ≈ 4× (10 → ~40G) | C7: NVIDIA BlueField-3 datasheet | D7: Ceiling then set by x86 policy processing
A8: Loaded cost / engineer | B8: ='2 · Investment'!B16 | C8: Internal planning estimate | D8: Default rate; individual roles can differ (Investment · drill-down B)
A9: Total investment (NRE) | B9: ='2 · Investment'!B9 | C9: Internal planning estimate | D9: Live link to the Investment total — changes with the inputs
A10: R&D team (FTE) | B10: ='2 · Investment'!B17 | C10: Internal planning estimate | D10: Fully-loaded; most sit on the offload boundary
A11: Duration to GA (months) | B11: ='2 · Investment'!B18 | C11: Internal planning estimate | D11: Effort estimate, not a schedule commitment
A12: Top risk | B12: Offload boundary (TP gain) | C12: Internal planning estimate | D12: Mitigated by a TLS-focused PoC gate before full commitment
A14: Investment at a glance (live from the Investment sheet)
A15: Workstream | B15: Amount (USD) | C15: % of total | D15: Basis / source
A16: R&D · engineers × duration | B16: ='2 · Investment'!B5 | C16: ='2 · Investment'!C5 | D16: Internal planning estimate
A17: HW engineering · thermal · FIPS | B17: ='2 · Investment'!B6 | C17: ='2 · Investment'!C6 | D17: CP Appliance Comparison Chart 2026
A18: Dev kits · NVIDIA NRE | B18: ='2 · Investment'!B7 | C18: ='2 · Investment'!C7 | D18: NVIDIA BlueField-3 datasheet
A19: GTM · launch | B19: ='2 · Investment'!B8 | C19: ='2 · Investment'!C8 | D19: Internal planning estimate
A20: Total | B20: ='2 · Investment'!B9 | C20: ='2 · Investment'!C9
A22: Throughput logic — which numbers are datasheet vs. estimate
A23: 9800 published (CP Appliance Chart 2026): 400G raw · 67.7G NGFW · 25G TP · 10.1G TP+TLS. Only the final ~40G is an estimate — everything else is a datasheet number, and the multiples are just division.
A24: Step | B24: TP+TLS | C24: Datasheet / estimate | D24: How we get the number
A25: Today — on the x86 | B25: 10.1G | C25: Datasheet | D25: 9800 "TP with HTTPS inspection" (published)
A26: The TLS tax | B26: 25G → 10.1G | C26: Datasheet | D26: TLS decrypt + inspect + re-encrypt on the x86 costs about 2.5x (25 / 10.1 = 2.48x)
A27: Offload TLS → BF-3 | B27: ~25G | C27: Anchored to datasheet | D27: Removes the TLS tax -> back to the 25G plain-TP ceiling
A28: Offload IPS (RXP) → BF-3 | B28: ~40G | C28: Estimate (only soft number) | D28: Climbs above 25G TP toward the 67.7G NGFW number; ~40G, limited by x86 policy
A29: Expected multiple | B29: ≈ 4× | C29: Derived | D29: 40 / 10.1 = 3.96x ~ 4x
A30: PoC Go / No-Go gate | B30: 25G+ (2.5×) | C30: Conservative target | D30: 25 / 10.1 = 2.48x - just recover the TLS tax
A31: Bottom line: 10.1G and 25G are the 9800’s own datasheet numbers; offloading TLS just returns you to 25G. Offloading IPS is the estimated step that adds the rest to ~40G — bounded above by the 67.7G NGFW figure and limited by x86 policy. The PoC validates that single soft number.
A33: Check Point Software Technologies · Confidential | Barak Rozenfeld · Senior PM Assignment 2026 | Slide 15 | Cream = editable input · grey = formula (recalculates).

Sheet 2 · Investment
A1: Investment — dynamic cost model with drill-down
A2: Edit the cream cells (salary, overhead, quantities, unit costs, and the per-role engineer rates). Grey cells are formulas; totals roll up automatically. Each line shows its basis/source and assumption.
A3: Cost summary · rolls up from the drill-down blocks below
A4: Category | B4: Amount (USD) | C4: % of total | E4: Basis / source | F4: Assumption
A5: R&D (engineers × role rate × years) | B5: =D27 | C5: =B5/$B$9 | E5: Internal planning estimate | F5: Rolls up from the per-role build-up (drill-down B)
A6: Hardware engineering · thermal · FIPS | B6: =D34 | C6: =B6/$B$9 | E6: CP Appliance Comparison Chart 2026 | F6: Mechanical/thermal, PSU validation, FIPS lab
A7: Dev kits / NRE | B7: =D42 | C7: =B7/$B$9 | E7: NVIDIA BlueField-3 datasheet | F7: BF-3 boards, DOCA, NVIDIA NRE, lab/test
A8: GTM / launch | B8: =D49 | C8: =B8/$B$9 | E8: Internal planning estimate | F8: Beta, launch, enablement, PoC support
A9: Total | B9: =SUM(B5:B8) | C9: =B9/$B$9
A10: Hardware eng. | B10: Card bring-up · thermal · FIPS lab | C10: CP Appliance Comparison Chart 2026 | D10: Mechanical/thermal design, PSU validation, FIPS 140-3 test lab
A11: Drill-down A · R&D engineer cost build-up
A12: Driver | B12: Value | C12: Unit | E12: Basis / source | F12: Assumption
A13: Base salary | B13: 170000 | C13: $ / year | E13: Internal planning estimate | F13: Blended senior-engineer base salary
A14: Overhead multiplier | B14: 0.4 | C14: × of salary | E14: Internal planning estimate | F14: Benefits, facilities, management, G&A
A15: Tooling & licenses | B15: 12000 | C15: $ / eng / yr | E15: Internal planning estimate | F15: Dev tools, cloud, lab share per engineer
A16: Default loaded cost / engineer | B16: =B13*(1+B14)+B15 | C16: $ / year | E16: Internal planning estimate | F16: Default rate; each role in drill-down B defaults to this and can be tuned by seniority
A17: Engineers (FTE) | B17: 12 | C17: FTE | E17: Internal planning estimate | F17: Most sit on the CoreXL↔card offload boundary
A18: Duration | B18: 18 | C18: months | E18: Internal planning estimate | F18: Effort estimate to GA, not a schedule commitment
A19: Duration (years) = months ÷ 12 | B19: =B18/12 | C19: years | E19: Internal planning estimate | F19: Forward factor used by the role table: cost = engineers × rate/yr × years
A20: Validation / performance | B20: PoC, automation, perf & regression | C20: Internal planning estimate | D20: Measures the real gain before full commitment | E20: 2 | F20: =$B$6
A21: Drill-down B · R&D headcount by role (engineers should sum to the FTE above)
A22: Role | B22: Engineers | C22: Loaded $/yr · per person | D22: Cost (USD) | E22: Basis / source | F22: Assumption
A23: DOCA bring-up / Gaia driver | B23: 3 | C23: 260000 | D23: =B23*C23*$B$19 | E23: Check Point AI Cloud Protect (AIFF) press release | F23: Driver/kernel specialists — rate above blended
A24: Offload API / CoreXL (the core) | B24: 5 | C24: 260000 | D24: =B24*C24*$B$19 | E24: Internal planning estimate | F24: Senior core engineers — where most of the risk sits
A25: Signature compiler (RXP) | B25: 2 | C25: 250000 | D25: =B25*C25*$B$19 | E25: NVIDIA BlueField-3 datasheet | F25: RXP / compiler specialists — blended rate
A26: Validation / performance | B26: 2 | C26: 210000 | D26: =B26*C26*$B$19 | E26: Internal planning estimate | F26: QA / performance mix — below blended
A27: Subtotal R&D · flows to the Cost summary (R&D row) | B27: =SUM(B23:B26) | D27: =SUM(D23:D26)
A29: Drill-down C · Hardware engineering
A30: Item | B30: Qty | C30: Unit cost | D30: Cost (USD) | E30: Basis / source | F30: Assumption
A31: Mechanical & thermal design | B31: 1 | C31: 500000 | D31: =B31*C31 | E31: Internal planning estimate | F31: 1RU airflow, chassis & card mechanics
A32: PSU / signal-integrity validation | B32: 1 | C32: 300000 | D32: =B32*C32 | E32: CP Appliance Comparison Chart 2026 | F32: Electrical headroom for ~75W added
A33: FIPS 140-3 lab & certification | B33: 1 | C33: 400000 | D33: =B33*C33 | E33: NIST CMVP (FIPS 140-3) | F33: BF-3 crypto module already approved
A34: Subtotal | D34: =SUM(D31:D33) | E34: → feeds the Cost summary
A36: Drill-down D · Dev kits / NRE
A37: Item | B37: Qty | C37: Unit cost | D37: Cost (USD) | E37: Basis / source | F37: Assumption
A38: BF-3 development boards | B38: 10 | C38: 15000 | D38: =B38*C38 | E38: NVIDIA BlueField-3 datasheet | F38: Dev/test units for the engineering team
A39: DOCA SDK / support | B39: 1 | C39: 120000 | D39: =B39*C39 | E39: NVIDIA BlueField-3 datasheet | F39: SDK, licenses and developer support
A40: NVIDIA NRE / integration | B40: 1 | C40: 400000 | D40: =B40*C40 | E40: NVIDIA BlueField-3 datasheet | F40: Non-recurring engineering with NVIDIA
A41: Lab / test equipment | B41: 1 | C41: 130000 | D41: =B41*C41 | E41: Internal planning estimate | F41: Traffic generators, TLS test harness
A42: Subtotal | D42: =SUM(D38:D41) | E42: → feeds the Cost summary
...

Sheet 3 · Timeline
A1: Delivery timeline — 18-month effort (with PoC gate)
A2: Effort allocation (person-/calendar-months), not a committed schedule; phases overlap. The Proof of Concept is an integral Go/No-Go gate.
A4: Phase | B4: Focus | C4: Effort (mo) | D4: Window | E4: Key deliverables | F4: Exit criterion / milestone | G4: Basis / source | H4: Assumption
A5: DOCA bring-up | B5: Gaia driver + DOCA SDK on BF-3 (based on the AIFF gateway) | C5: 3 | D5: M0 – M3 | E5: Driver loads; zero-copy DMA path | F5: Traffic passes through the card | G5: Check Point AI Cloud Protect (AIFF) press release | H5: Reuse the AIFF containerized gateway already on BF-3
A6: Offload API (the core) | B6: CoreXL ↔ card API; TLS decrypt/re-encrypt + IPS offload | C6: 5 | D6: M3 – M8 | E6: TLS offloaded to the DPU engines | F6: Offload path functional end-to-end | G6: Internal planning estimate | H6: Most of the engineers; the core technical work
A7: Proof of Concept · TLS gate | B7: Measure the real TP+TLS gain on a 9800 + BF-3 before full commitment | C7: 2 | D7: M8 – M10 | E7: Benchmarked 9800 + card under TLS inspection | F7: Go / No-Go gate: 25G+ TP under TLS | G7: CP Appliance Comparison Chart 2026 | H7: De-risks the offload-boundary assumption before RXP/FIPS spend
A8: RXP + FIPS | B8: IPS DB → RXP signature compiler; FIPS 140-3 filed early | C8: 4 | D8: M10 – M14 | E8: ~85% of signatures compiled; FIPS filed | F8: Hybrid IPS gain measured; FIPS in review | G8: NIST CMVP (FIPS 140-3) | H8: FIPS filed ~9 mo before GA; BF-3 crypto module approved
A9: Beta → GA | B9: Design-partner beta, hardening, launch | C9: 4 | D9: M14 – M18 | E9: Beta with design partners; GTM ready | F9: General Availability (GA) | G9: Internal planning estimate | H9: Design-partner program before GA
A10: Total effort | C10: =SUM(C5:C9)
A11: Note: effort months sum to 18; calendar windows overlap. FIPS 140-3 is submitted ≈ 9 months before GA (not after).
A12: Note: effort months sum to 18; calendar windows overlap. The PoC (M8–M10) is a Go/No-Go gate — the project only commits to RXP/FIPS spend after 25G+ under TLS is demonstrated. FIPS 140-3 is submitted ≈ 9 months before GA.
A13: Check Point Software Technologies · Confidential | Barak Rozenfeld · Senior PM Assignment 2026 | Session 1 · Slide 15 — What it takes to deliver the solution | Edit the yellow input cells; grey cells are formulas.
A14: Check Point Software Technologies · Confidential | Barak Rozenfeld · Senior PM Assignment 2026 | Slide 15 | Cream = editable input · grey = formula (recalculates).

Sheet 4 · Requirements
A1: Requirements to deliver
A2: Hardware, software/integration and product readiness — each with a target metric, its basis/source and the assumption to validate.
A4: Domain | B4: Requirement | C4: Detail | D4: Target metric | E4: Basis / source | F4: Assumption / to validate
A5: Hardware | B5: Form factor | C5: Acceleration card in one of the two network I/O slots of the 9700/9800 | D5: 1 of 2 I/O slots | E5: Quantum Force 9800 datasheet | F5: Check Point card model, not a generic PCIe x16 slot
B6: Power & thermal | C6: ~75W extra; verify PSU headroom and airflow in 1RU | D6: ≤ ~75W added | E6: CP Appliance Comparison Chart 2026 | F6: Early thermal sim; if no headroom → factory option next gen
B7: Data path | C7: Zero-copy DMA without degrading the firewall-path latency | D7: 1.85µs FW path preserved | E7: CP Appliance Comparison Chart 2026 | F7: DMA integration validated in PoC
A8: Software & integration | B8: Gaia driver + DOCA SDK | C8: Based on the AIFF containerized gateway, already on BF-3 | D8: Reuse AIFF stack | E8: Check Point AI Cloud Protect (AIFF) press release | F8: Vendor relationship & platform already in production
B9: Offload boundary | C9: The API between CoreXL and the card — most of the 12 engineers | D9: TP ≥ 25G under TLS | E9: Internal planning estimate | F9: Core technical risk; measured in the PoC
B10: Signature compiler | C10: Converting the IPS DB → RXP; metric is % of signatures that compile | D10: ~85% signatures compile | E10: NVIDIA BlueField-3 datasheet | F10: Partial IPS acceptable — TLS offload delivers most of the gain
A11: Product readiness | B11: Certification | C11: Maintain FIPS 140-3; assess the card’s impact on CC certification | D11: FIPS filed ~9 mo pre-GA | E11: NIST CMVP (FIPS 140-3) | F11: BF-3 already has an approved crypto module; submit early
B12: Customer experience | C12: No change to SmartConsole or to the existing security policy | D12: Zero policy change | E12: Internal planning estimate | F12: Transparent to existing deployments
B13: Launch | C13: Beta with design partners before GA | D13: Beta → GA | E13: Internal planning estimate | F13: Design-partner program defined
A15: Check Point Software Technologies · Confidential | Barak Rozenfeld · Senior PM Assignment 2026 | Session 1 · Slide 15 — What it takes to deliver the solution | Edit the yellow input cells; grey cells are formulas.

Sheet 5 · Risk register
A1: Risk register
A2: Severity × Likelihood (High=3, Medium=2, Low=1; Score = S×L). Each risk carries its basis/source, mitigation and a measurable target.
A4: # | B4: Risk | C4: Description | D4: Severity | E4: Likelihood | F4: Score | G4: Mitigation | H4: Measurable target (KPI) | I4: Basis / source | J4: Owner
A5: 1 | B5: Offload boundary | C5: Threat-Prevention throughput does not rise as expected once offloaded | D5: High | E5: Medium | F5: 6 | G5: A TLS-focused PoC gate that measures the real gain before full commitment | H5: 25G+ under TLS | I5: Internal planning estimate | J5: R&D
A6: 2 | B6: Signature coverage on RXP | C6: Only part of the IPS signatures compile to RXP → partial IPS gain | D6: Medium | E6: Medium | F6: 4 | G6: Not dependent on IPS: TLS offload alone delivers most of the gain (hybrid) | H6: ~85% signatures | I6: NVIDIA BlueField-3 datasheet | J6: R&D
A7: 3 | B7: Power / thermal in 1RU | C7: No electrical / airflow headroom for the card in the 1RU box | D7: Medium | E7: Low | F7: 2 | G7: Early thermal simulation; if no headroom → factory option next generation | H7: ~75W added | I7: CP Appliance Comparison Chart 2026 | J7: HW engineering
A8: 4 | B8: Dependence on NVIDIA | C8: Single vendor in the data path | D8: Medium | E8: Low | F8: 2 | G8: Multi-year AIFF agreement + abstraction layer to switch vendors in gen 2 | H8: 2 vendor options | I8: Check Point AI Cloud Protect (AIFF) press release | J8: Product / Procurement
A9: 5 | B9: FIPS / CC re-certification | C9: Re-certification risk for regulated customers | D9: Low | E9: Low | F9: 1 | G9: Early FIPS submission (not after GA); BF-3 already has an approved crypto module | H9: ~9 mo before GA | I9: NIST CMVP (FIPS 140-3) | J9: Compliance
A11: Legend — Severity/Likelihood: High (3) · Medium (2) · Low (1). Score 6 = red, 3–4 = amber, 1–2 = green. Risk severity ranking is a qualitative assessment.
A13: Check Point Software Technologies · Confidential | Barak Rozenfeld · Senior PM Assignment 2026 | Slide 15 | Cream = editable input · grey = formula (recalculates).

Sheet 6 · ROI
A1: ROI — 3-year business case (expanded from Slide 16)
A2: Why the numbers, how they are built, and the sales assumptions (incl. 29100/29200 cannibalization). Cream = editable input · grey = formula. The one-time investment links live to the Investment sheet.
A4: Headline — 3-year outcome (base vs. base + deal upside)
A5: Metric | B5: Base | C5: Base + upside | E5: Basis / source | F5: Assumption
A6: 3-year revenue | B6: =B44 | C6: =C44 | E6: Build-ups A & B + upside deals | F6: Module revenue, plus DC/HQ deal revenue in the upside
A7: Gross profit | B7: =B45 | C7: =C45 | E7: Margins applied per line | F7: 65% on modules, 60% on DC/HQ deals
A8: Net contribution (3 yr) | B8: =B47 | C8: =C47 | E8: Gross profit − cannibalization − investment | F8: One-time investment is a planning estimate
A9: ROI (3 yr) | B9: =B48 | C9: =C48 | E9: Net ÷ investment | F9: Net ÷ investment, net of cannibalization; deck shows ~189% / ~408% (sheet exact)
A10: Break-even (months from GA) | B10: 16 | C10: — | E10: Modules only | F10: Demand concentrated in year 1
A12: Key inputs — editable (cream); each with its basis and assumption
A13: Driver | B13: Value | C13: Unit | E13: Basis / source | F13: Assumption
A14: Module price (ASP uplift) | B14: 15000 | C14: $ / module | E14: IDC + Check Point IR, planning | F14: List before channel discount; the uplift added to a deal
A15: Annual 9700/9800 shipments | B15: 1500 | C15: units / yr | E15: IDC Security Appliance Tracker | F15: New-unit base the module attaches to
A16: Attach rate — year 1 | B16: 0.3 | C16: % | E16: Planning | F16: Ramp start, first year after GA
A17: Attach rate — year 2 | B17: 0.4 | C17: % | E17: Planning | F17: Mid ramp
A18: Attach rate — year 3 | B18: 0.5 | C18: % | E18: Planning | F18: Mature attach rate
A19: Installed-base upgrades (3 yr) | B19: 925 | C19: modules | E19: Planning | F19: Share of the installed base upgrading; demand concentrated in year 1
A20: Gross margin — module | B20: 0.65 | C20: % | E20: Check Point product standard | F20: Blended software + hardware module margin
A21: Gross margin — DC/HQ deal | B21: 0.6 | C21: % | E21: Check Point deal standard | F21: Hardware-heavy deal margin
A22: One-time investment | B22: ='2 · Investment'!B9 | C22: $ | E22: Live link → '2 · Investment'!B9 | F22: Planning estimate: R&D, HW+FIPS, dev kits, GTM
A23: Horizon | B23: 3 | C23: years | E23: Standard business case | F23: 3-year planning horizon
A24: DC/HQ deals won / yr (upside) | B24: 25 | C24: deals / yr | E24: Planning (+10 pts win-rate) | F24: Incremental wins from the 4× TP+TLS advantage
A25: DC/HQ deal value (upside) | B25: 350000 | C25: $ / deal | E25: Planning | F25: Average DC/HQ deal ASP
A27: Build-up A — attach on new units (how 1,800 modules & $27.0M arise)
A28: Year | B28: New units | C28: Attach % | D28: Modules | E28: Revenue | F28: Assumption
A29: Year 1 | B29: =$B$15 | C29: =B16 | D29: =B29*C29 | E29: =D29*$B$14 | F29: Ramp start
A30: Year 2 | B30: =$B$15 | C30: =B17 | D30: =B30*C30 | E30: =D30*$B$14 | F30: Mid ramp
A31: Year 3 | B31: =$B$15 | C31: =B18 | D31: =B31*C31 | E31: =D31*$B$14 | F31: Mature attach
A32: Subtotal | D32: =SUM(D29:D31) | E32: =SUM(E29:E31) | F32: 1,800 modules over 3 years as attach grows 30% → 50%
A34: Build-up B — base module revenue (3 years)
A35: Component | C35: Modules | D35: Revenue | E35: Basis / source | F35: Assumption
A36: Attach on new units | C36: =D32 | D36: =E32 | E36: Build-up A | F36: New-unit attach, years 1–3
A37: Installed-base upgrades | C37: =$B$19 | D37: =$B$19*$B$14 | E37: Planning | F37: 925 upgrades × $15K; demand concentrated in year 1
A38: Total module revenue | C38: =C36+C37 | D38: =D36+D37 | F38: Flows into the ROI waterfall as base revenue
A40: ROI waterfall — base vs. base + deal upside
A41: Line | B41: Base | C41: Base + upside | E41: Basis / source | F41: Assumption
A42: Module revenue (3 yr) | B42: =D38 | C42: =D38 | E42: Build-up B | F42: Same in both scenarios
A43: DC/HQ deal revenue (upside) | B43: 0 | C43: =$B$23*$B$24*$B$25 | E43: Upside only | F43: 75 deals (25/yr × 3) × $350K
A44: Total revenue | B44: =B42+B43 | C44: =C42+C43 | F44: Module + upside deals
A45: Gross profit | B45: =D38*$B$20 | C45: =D38*$B$20+C43*$B$21 | E45: Margins per line | F45: 65% module · 60% deal
...

Sheet 12 · Alternatives
A1: Slide 12 — Four alternatives for accelerating TP under TLS
A2: Each alternative has its own sheet with a bottom-up breakdown of how the time and cost were derived. Criterion: throughput per RU without sacrificing flexibility.
A4: # | B4: Alternative | C4: What we develop | D4: Dev time | E4: Dev cost (NRE) | F4: Throughput (today 10) & verdict
A5: 1 | B5: Build our own ASIC | C5: Our own dedicated chip | D5: 3–5 years | E5: $300M+ | F5: ~40+ · Rejected — cost & time prohibitive, inflexible
A6: 2 | B6: Self-designed FPGA | C6: FPGA designed by Check Point | D6: ~3 years | E6: $30–50M | F6: ~30–40 · Rejected — costly, HDL per engine
A7: 3 | B7: Use a ConnectX-7 SmartNIC | C7: Off-the-shelf NVIDIA ConnectX-7 | D7: ~12 months | E7: ~$3M | F7: 10→~20 (×2) · Rejected — crypto only, no Arm cores
A8: ✓ | B8: Use a BlueField-3 card (CHOSEN) | C8: Existing NVIDIA BlueField-3 card | D8: ~18 months | E8: ~$7M | F8: 10→~40 (×4) · CHOSEN — best TP/RU + software-updatable
A10: Basis: ASIC/FPGA are industry precedent (IBS/McKinsey); ConnectX & BlueField-3 are our bottom-up estimate. Throughput for ASIC/FPGA is a qualitative comparison.

Sheet Alt 1 — Own ASIC
A1: Alternative 1 — Build our own ASIC
A2: A Check Point-designed dedicated chip. Rejected: cost and time are prohibitive and the logic is burned into silicon — a new engine means a whole new hardware generation.
A4: Headline
A5: Metric | B5: Value | C5: Basis
A6: Development time | B6: 3–5 years | C6: Tape-out (~2 yr) + bring-up + software; industry precedent
A7: Development cost (NRE) | B7: $300M+ | C7: 7nm full design cost (IBS / McKinsey chip-design cost by node)
A8: Throughput (TP+TLS/RU) | B8: ~40+ | C8: Reaches the target; x86 policy stage then the limit (qualitative)
A9: Verdict | B9: Rejected | C9: Highest cost, longest time, zero flexibility for new engines / AI-ML
A11: How the development TIME was derived
A12: Phase | B12: Duration | C12: Why this long
A13: Architecture + RTL design | B13: ~12 months | C13: Specify the crypto + inspection pipelines and write the RTL
A14: Verification & validation | B14: ~12 months | C14: Exhaustive sim/formal; a silicon bug after tape-out is catastrophic
A15: Physical design + 7nm tape-out | B15: ~6–12 months | C15: Place-and-route, mask set, fab; ~2 yr cumulative to first silicon
A16: Fab + first silicon + bring-up | B16: ~6 months | C16: Wafer run, packaging, lab bring-up
A17: Respin (typical) + re-validation | B17: ~6–12 months | C17: First silicon rarely ships; budget at least one respin
A18: Firmware + Gaia/platform integration | B18: ~6–12 months | C18: Drivers and software stack, overlaps bring-up
A19: Calendar total (with overlap) | B19: 3–5 years | C19: Industry precedent for a new security ASIC
A21: How the development COST (NRE) was derived
A22: Component | B22: Amount | C22: Note / assumption
A23: IP licensing + architecture + RTL | B23: 55000000 | C23: Licensed crypto/networking IP + design team
A24: Verification & validation | B24: 60000000 | C24: Largest single line in modern SoC design
A25: Physical design + 7nm mask set | B25: 45000000 | C25: Masks alone ~$15–25M at 7nm, plus place-and-route
A26: Prototyping, bring-up, 1 respin | B26: 40000000 | C26: Each respin ~$5–15M in masks + lost time
A27: Firmware + software + drivers | B27: 45000000 | C27: Full stack to run on the new silicon
A28: Qualification, FIPS/EAL, PM, overhead | B28: 55000000 | C28: Certification + multi-year program overhead
A29: Total NRE (≈ IBS/McKinsey 7nm) | B29: =B23+B24+B25+B26+B27+B28 | C29: Sums to ~$300M; '+': extra respins push well beyond

Sheet Alt 2 — FPGA
A1: Alternative 2 — Self-designed FPGA
A2: An FPGA designed by Check Point. Rejected: still costly, every new engine needs fresh HDL work, and performance trails a custom ASIC. The $30–50M range below is built bottom-up to a ~$40M midpoint.
A4: Headline
A5: Metric | B5: Value | C5: Basis
A6: Development time | B6: ~3 years | C6: HDL + timing closure; no tape-out, so shorter than an ASIC
A7: Development cost (NRE) | B7: $30–50M | C7: Bottom-up ~$40M; range driven by team size & board respins
A8: Throughput (TP+TLS/RU) | B8: ~30–40 | C8: Frequency / logic-density gap versus a custom ASIC (qualitative)
A9: Verdict | B9: Rejected | C9: Costly, HDL effort per new engine, slower than an ASIC
A11: How the development TIME was derived
A12: Phase | B12: Duration | C12: Why this long
A13: Architecture + HDL design | B13: ~12–15 months | C13: RTL for the crypto + inspection pipelines
A14: Verification + timing closure | B14: ~9–12 months | C14: Timing closure on advanced FPGAs is the long pole
A15: Board/card design + bring-up | B15: ~6–9 months | C15: Overlaps HDL; custom card around the FPGA
A16: Firmware/driver + integration | B16: ~6 months | C16: Into Gaia / the 9000 platform
A17: Qualification / certification | B17: ~6 months | C17: FIPS / EAL on the new card
A18: Calendar total (with overlap) | B18: ~3 years | C18: No tape-out, so ~1–2 yr shorter than an ASIC
A20: How the development COST (NRE) was derived
A21: Component | B21: Amount | C21: Note / assumption
A22: FTE — HDL/verif/firmware/board team | B22: 25 | C22: Specialist HDL engineers are scarce & expensive
A23: Years | B23: 3 | C23: Matches the ~3-year timeline above
A24: Loaded cost per FTE-year | B24: 280000 | C24: Fully loaded (salary + overhead + tools share)
A25: Engineering team | B25: =B22*B23*B24
A26: EDA + FPGA tool licenses (3 yr) | B26: 4000000 | C26: Synopsys/Cadence/FPGA vendor toolchains
A27: Board design + 3 respins + prototypes | B27: 6000000 | C27: Main swing factor for the $30–50M range
A28: Premium FPGA silicon (dev + qual lots) | B28: 3000000 | C28: High-end Versal/Agilex-class parts
A29: Qualification & certification (FIPS/EAL) | B29: 3000000 | C29: Regulated-market certification
A30: Program mgmt + contingency | B30: 3000000 | C30: PM, risk buffer
A31: Total NRE (midpoint of $30–50M) | B31: =B25+B26+B27+B28+B29+B30 | C31: ≈$40M; 20 FTE & fewer respins → ~$30M, 30 FTE & more → ~$50M

Sheet Alt 3 — ConnectX NIC
A1: Alternative 3 — Use a ConnectX-7 SmartNIC
A2: An off-the-shelf NVIDIA ConnectX-7 NIC. Rejected: fixed-function offload (inline TLS/IPsec crypto only) with no programmable Arm cores, so it cannot run IPS or an AI/ML engine on-card.
A4: Headline
A5: Metric | B5: Value | C5: Basis
A6: Development time | B6: ~12 months | C6: Driver + crypto-offload integration on an off-the-shelf NIC
A7: Development cost (NRE) | B7: ~$3M | C7: Bottom-up; cheapest option but limited capability
A8: Throughput (TP+TLS/RU) | B8: 10 → ~20 (×2) | C8: TLS crypto offload only; IPS still runs on the x86
A9: Verdict | B9: Rejected | C9: Relieves only TLS crypto; the x86 stays the inspection bottleneck
A11: How the development TIME was derived
A12: Phase | B12: Duration | C12: Why this long
A13: Driver bring-up in Gaia | B13: ~6 months | C13: Standard NIC driver model; no on-card OS to build
A14: TLS/IPsec crypto-offload integration | B14: ~6 months | C14: Wire inline crypto offload into the data path (overlaps driver)
A15: Calendar total (with overlap) | B15: ~12 months | C15: Off-the-shelf NIC, no DPU software stack to build
A17: How the development COST (NRE) was derived
A18: Component | B18: Amount | C18: Note / assumption
A19: FTE — integration team | B19: 6 | C19: Small team; no on-card software platform
A20: Years | B20: 1 | C20: Matches the ~12-month timeline
A21: Loaded cost per FTE-year | B21: 250000 | C21: Fully loaded
A22: Engineering team | B22: =B19*B20*B21
A23: ConnectX-7 dev cards + lab setup | B23: 300000 | C23: Off-the-shelf hardware
A24: Test tooling | B24: 200000 | C24: Traffic generators, test rigs
A25: Qualification (no new silicon) | B25: 500000 | C25: Lighter — reusing a shipping NIC
A26: Contingency | B26: 500000 | C26: Risk buffer
A27: Total NRE | B27: =B22+B23+B24+B25+B26 | C27: Sums to ~$3M

Sheet Alt 4 — BlueField-3 (chosen)
A1: Alternative 4 — Use a BlueField-3 acceleration card ✓ CHOSEN
A2: An existing NVIDIA BlueField-3 card in a Check Point-format slot. Chosen: best throughput per RU without sacrificing flexibility — a new engine (incl. AI/ML) ships as a software update, and BF-3 is already proven in Check Point AI Cloud Protect (AIFF). Cream = editable input · grey = formula.
A4: Headline
A5: Metric | B5: Value | C5: Basis
A6: Development time | B6: ~18 months | C6: ~12 mo integration + ~6 mo PoC on an existing BF-3
A7: Development cost (NRE) | B7: ~$7M | C7: Bottom-up: team + dev kits + tooling + cert + contingency
A8: Throughput (TP+TLS/RU) | B8: 10 → ~40 (×4) | C8: Offloads TLS crypto + IPS; PoC gate is a conservative 25G+ (×2.5)
A9: Verdict | B9: CHOSEN | C9: Best TP/RU, software-updatable, vendor + platform already proven
A11: How the development TIME was derived
A12: Phase | B12: Duration | C12: Why this long
A13: Integration | B13: 12 months | C13: Card in the I/O slot, drivers, TLS+IPS offload pipeline in Gaia
A14: PoC | B14: 6 months | C14: Validate 25G+ gate, power / thermal / mechanical fit in the card format
A15: Calendar total | B15: 18 months | C15: Not from scratch — the 9000 already runs acceleration cards; BF-3 is in AIFF
A17: How the development COST (NRE) was derived
A18: Component | B18: Amount | C18: Note / assumption
A19: Engineers | B19: 12 | C19: Core R&D team for integration + PoC
A20: Duration (months) | B20: 18 | C20: Integration + PoC window
A21: Loaded cost per engineer-month | B21: 20833 | C21: ≈ $250K / engineer-year, fully loaded
A22: R&D team | B22: =B19*B20*B21
A23: BlueField-3 dev kits | B23: 800000 | C23: NVIDIA BF-3 development hardware
A24: Lab + test tooling | B24: 600000 | C24: Traffic generators, test rigs, bench
A25: FIPS / certification pre-work | B25: 600000 | C25: Early cert groundwork during the PoC
A26: Contingency | B26: 500000 | C26: Risk buffer for the PoC phase
A27: Total NRE | B27: =B22+B23+B24+B25+B26 | C27: Sums to ~$7.0M. The full program on '2 · Investment' is $7.2M (adds HW/FIPS + GTM beyond this R&D+PoC core)

Sheet PoC — detail
A1: PoC — detailed plan (investment structure + effort timeline)
A2: The $2.9M / ~6-month Proof-of-Concept that must clear ONE gate (25 Gbps+ under TLS) before the $4.3M GA spend is released. Cream = editable input · grey = formula (recalculates).
A4: Headline
A5: Metric | B5: Value | C5: Basis
A6: Success gate | B6: 25 Gbps+ under TLS (×2.5) | C6: Primary exit criterion vs 10G under TP+TLS today
A7: Duration | B7: ~6 months | C7: Effort estimate, not a schedule commitment
A8: PoC cost | B8: =D30 | C8: Bottom-up total of the investment structure below
A9: Team | B9: 10 engineers | C9: Focused subset on the offload boundary
A10: Held back to GA | B10: $4.3M | C10: Released only if the gate is met — otherwise we stop
A12: Investment structure · PoC — bottom-up to $2.9M
A13: R&D build-up
A14: Engineers (PoC) | B14: 10 | E14: Focused subset — core offload + driver + perf
A15: Duration | B15: 6 | C15: months | E15: To the 25 Gbps+ gate
A16: Loaded cost / engineer-month | B16: 20833 | E16: =default loaded $250K/yr ÷ 12 (see Investment sheet)
A17: R&D subtotal = engineers × months × rate | D17: =B14*B15*B16 | E17: ≈ $1.25M
A19: Line item (dev kits / HW / GTM) | B19: Qty | C19: Unit cost | D19: Amount | E19: Note
A20: BF-3 dev boards | B20: 6 | C20: 15000 | D20: =B20*C20 | E20: Dev/test units for the PoC team
A21: DOCA SDK / support | B21: 1 | C21: 120000 | D21: =B21*C21 | E21: SDK, licenses and developer support
A22: NVIDIA NRE (PoC portion) | B22: 1 | C22: 330000 | D22: =B22*C22 | E22: Non-recurring integration engineering
A23: Lab / TLS test harness | B23: 1 | C23: 110000 | D23: =B23*C23 | E23: Traffic generators + TLS test rig
A24: Early thermal / airflow simulation | B24: 1 | C24: 300000 | D24: =B24*C24 | E24: 1RU airflow for ~75W added
A25: PSU / signal-integrity pre-check | B25: 1 | C25: 150000 | D25: =B25*C25 | E25: Electrical headroom validation
A26: FIPS 140-3 scoping | B26: 1 | C26: 150000 | D26: =B26*C26 | E26: Early cert groundwork (BF-3 module already approved)
A27: Design-partner program prep | B27: 1 | C27: 250000 | D27: =B27*C27 | E27: Line up beta partners before GA
A28: PoC engineering support | B28: 1 | C28: 150000 | D28: =B28*C28 | E28: Field / SE support during the PoC
A29: Non-R&D subtotal | D29: =SUM(D20:D28) | E29: dev kits/NRE $0.65M + HW/thermal/FIPS $0.6M + GTM $0.4M
A30: TOTAL PoC = R&D + non-R&D | D30: =D17+D29 | E30: ≈ $2.9M (phase-slice of the $7.2M full program)
A32: Effort timeline · PoC — phases sum to ~6 months
A33: Phase | B33: Months | D33: What happens / output
A34: Dev-kit & lab bring-up | B34: 1 | D34: Set up BF-3 boards, lab and baseline — environment ready
A35: Offload integration (core) | B35: 2 | D35: DOCA/Gaia driver + CoreXL offload path — TLS path running on the card
A36: TLS gate measurement (25G+) | B36: 2 | D36: Measure TP under TLS and tune — the make-or-break gate
A37: Thermal + FIPS scoping | B37: 1 | D37: 1RU thermal sim + FIPS path — headroom & cert path confirmed
A38: Total | B38: =SUM(B34:B37) | D38: ≈ 6 months to the gate
A40: Success gate & exit criteria
A41: Primary gate | B41: ≥ 25 Gbps TP under TLS (×2.5 vs 10G today) — the go/no-go number
A42: Secondary | B42: ~85% of IPS signatures compile on the RXP engine
A43: Thermal / power | B43: ~75W added fits within 1RU PSU & airflow headroom
A44: Certification | B44: FIPS 140-3 path confirmed — BF-3 crypto module already approved
A45: Exit rule | B45: If the primary gate is missed → stop before the $4.3M GA spend
